Logging to ./qwen_triton_sft/logs
Logging into HF

    _|    _|  _|    _|    _|_|_|    _|_|_|  _|_|_|  _|      _|    _|_|_|      _|_|_|_|    _|_|      _|_|_|  _|_|_|_|
    _|    _|  _|    _|  _|        _|          _|    _|_|    _|  _|            _|        _|    _|  _|        _|
    _|_|_|_|  _|    _|  _|  _|_|  _|  _|_|    _|    _|  _|  _|  _|  _|_|      _|_|_|    _|_|_|_|  _|        _|_|_|
    _|    _|  _|    _|  _|    _|  _|    _|    _|    _|    _|_|  _|    _|      _|        _|    _|  _|        _|
    _|    _|    _|_|      _|_|_|    _|_|_|  _|_|_|  _|      _|    _|_|_|      _|        _|    _|    _|_|_|  _|_|_|_|
Traceback (most recent call last):
  File "/home/ubuntu/.local/lib/python3.10/site-packages/huggingface_hub/utils/_http.py", line 409, in hf_raise_for_status
    response.raise_for_status()
  File "/home/ubuntu/.local/lib/python3.10/site-packages/requests/models.py", line 1024, in raise_for_status
    raise HTTPError(http_error_msg, response=self)
requests.exceptions.HTTPError: 401 Client Error: Unauthorized for url: https://huggingface.co/api/whoami-v2

The above exception was the direct cause of the following exception:

Traceback (most recent call last):
  File "/home/ubuntu/.local/lib/python3.10/site-packages/huggingface_hub/hf_api.py", line 1746, in whoami
    hf_raise_for_status(r)
  File "/home/ubuntu/.local/lib/python3.10/site-packages/huggingface_hub/utils/_http.py", line 482, in hf_raise_for_status
    raise _format(HfHubHTTPError, str(e), response) from e
huggingface_hub.errors.HfHubHTTPError: 401 Client Error: Unauthorized for url: https://huggingface.co/api/whoami-v2 (Request ID: Root=1-683cce01-0feefca72d8f5954017208f7;70e5e5cb-b45e-48fb-adbc-62c334648c26)

Invalid credentials in Authorization header

The above exception was the direct cause of the following exception:

Traceback (most recent call last):
  File "/home/ubuntu/rlptx/sft_grpo/trainer2.py", line 458, in <module>
    model = trainer_setup.train(
  File "/home/ubuntu/rlptx/sft_grpo/trainer2.py", line 310, in train
    login()
  File "/home/ubuntu/.local/lib/python3.10/site-packages/huggingface_hub/utils/_deprecation.py", line 101, in inner_f
    return f(*args, **kwargs)
  File "/home/ubuntu/.local/lib/python3.10/site-packages/huggingface_hub/utils/_deprecation.py", line 31, in inner_f
    return f(*args, **kwargs)
  File "/home/ubuntu/.local/lib/python3.10/site-packages/huggingface_hub/_login.py", line 130, in login
    interpreter_login(new_session=new_session)
  File "/home/ubuntu/.local/lib/python3.10/site-packages/huggingface_hub/utils/_deprecation.py", line 101, in inner_f
    return f(*args, **kwargs)
  File "/home/ubuntu/.local/lib/python3.10/site-packages/huggingface_hub/utils/_deprecation.py", line 31, in inner_f
    return f(*args, **kwargs)
  File "/home/ubuntu/.local/lib/python3.10/site-packages/huggingface_hub/_login.py", line 290, in interpreter_login
    _login(token=token, add_to_git_credential=add_to_git_credential)
  File "/home/ubuntu/.local/lib/python3.10/site-packages/huggingface_hub/_login.py", line 404, in _login
    token_info = whoami(token)
  File "/home/ubuntu/.local/lib/python3.10/site-packages/huggingface_hub/utils/_validators.py", line 114, in _inner_fn
    return fn(*args, **kwargs)
  File "/home/ubuntu/.local/lib/python3.10/site-packages/huggingface_hub/hf_api.py", line 1759, in whoami
    raise HTTPError(error_message, request=e.request, response=e.response) from e
requests.exceptions.HTTPError: Invalid user token.
